<?xml version="1.0"?>

<robot xmlns:xacro="http://www.ros.org/wiki/xacro" name="mobile_robot">

    <!-- 수정된 body 링크 -->
    <link name="body">
        <visual>
            <geometry>
                <box size="1.6 0.87 0.55"/> <!-- 수정된 크기 (1,600*1,160*550 mm) -->
            </geometry>
        </visual>

        <collision>
            <geometry>
                <box size="1.6 0.87 0.55"/> <!-- 수정된 크기 (1,600*1,160*550 mm) -->
            </geometry>
        </collision>

        <inertial>
          <mass value="150"/>
          <inertia ixx="0.4967" ixy="0.0" ixz="0" iyy="1.4967" iyz="0" izz="1.6667"/>
        </inertial>
    </link>

<!--............................................rf_wheel...................................................... -->  

    <link name= "rf_wheel">
        <visual>
	        <origin rpy="1.570795 0 0" xyz="0 0 0"/>
	        <geometry>
	            <cylinder length="0.33" radius="0.27"/>
	        </geometry>
        </visual>
      
        <collision>
	        <origin rpy="1.570795 0 0" xyz="0 0 0"/>
	            <geometry>
	                <cylinder length="0.33" radius="0.27"/>
	            </geometry>
        </collision>

        <inertial>
	        <origin rpy="1.570795 0 0" xyz="0 0 0"/> 
            <mass value="1"/>
            <inertia ixx="0.06583" ixy="0.0" ixz="0.0" iyy="0.06583" iyz="0.0" izz="0.125"/>
        </inertial>
    </link>

    <joint name="body_rf_wheel" type="continuous">
        <axis xyz="0 1 0"/>
        <parent link="body"/>
        <child link="rf_wheel"/>
        <origin rpy="0 0 0" xyz="0.7 -0.6 0"/>
        <limit effort="100" velocity="1.0"/>  
    </joint>

<!--............................................rb_wheel...................................................... -->        

    <link name= "rb_wheel">
        <visual>
	        <origin rpy="1.570795 0 0" xyz="0 0 0"/>
	        <geometry>
	            <cylinder length="0.33" radius="0.27"/>
	        </geometry>
        </visual>
      
        <collision>
	        <origin rpy="1.570795 0 0" xyz="0 0 0"/>
	        <geometry>
	            <cylinder length="0.33" radius="0.27"/>
	        </geometry>
        </collision>

        <inertial>
	        <origin rpy="1.570795 0 0" xyz="0 0 0"/> 
            <mass value="1"/>
            <inertia ixx="0.06583" ixy="0.0" ixz="0.0" iyy="0.06583" iyz="0.0" izz="0.125"/>
        </inertial>
    </link>

    <joint name="body_rb_wheel" type="continuous">
        <axis xyz="0 1 0"/>
        <parent link="body"/>
        <child link="rb_wheel"/>
        <origin rpy="0 0 0" xyz="-0.7 -0.6 0"/>
        <limit effort="100" velocity="1.0"/>
    </joint>

<!--............................................lf_wheel...................................................... -->      

    <link name= "lf_wheel">
        <visual>
	        <origin rpy="1.570795 0 0" xyz="0 0 0"/>
	        <geometry>
	            <cylinder length="0.33" radius="0.27"/>
	        </geometry>
        </visual>
      
        <collision>
	        <origin rpy="1.570795 0 0" xyz="0 0 0"/>
	        <geometry>
	            <cylinder length="0.33" radius="0.27"/>
	        </geometry>
        </collision>

        <inertial>
	        <origin rpy="1.570795 0 0" xyz="0 0 0"/> 
            <mass value="1"/>
            <inertia ixx="0.06583" ixy="0.0" ixz="0.0" iyy="0.06583" iyz="0.0" izz="0.125"/>
        </inertial>
    </link>

    <joint name="body_lf_wheel" type="continuous">
        <axis xyz="0 1 0"/>
        <parent link="body"/>
        <child link="lf_wheel"/>
        <origin rpy="0 0 0" xyz="0.7 0.6 0"/>
        <limit effort="100" velocity="1.0"/>
    </joint>

<!--............................................lb_wheel...................................................... -->  

    <link name= "lb_wheel">
        <visual>
	        <origin rpy="1.570795 0 0" xyz="0 0 0"/>
	        <geometry>
	            <cylinder length="0.33" radius="0.27"/>
	        </geometry>
        </visual>
      
        <collision>
	        <origin rpy="1.570795 0 0" xyz="0 0 0"/>
	        <geometry>
	            <cylinder length="0.33" radius="0.27"/>
	        </geometry>
        </collision>

        <inertial>
	        <origin rpy="1.570795 0 0" xyz="0 0 0"/> 
            <mass value="1"/>
            <inertia ixx="0.06583" ixy="0.0" ixz="0.0" iyy="0.06583" iyz="0.0" izz="0.125"/>
        </inertial>
    </link>

    <joint name="body_lb_wheel" type="continuous">
        <axis xyz="0 1 0"/>
        <parent link="body"/>
        <child link="lb_wheel"/>
        <origin rpy="0 0 0" xyz="-0.7 0.6 0"/>
        <limit effort="100" velocity="1.0"/>
    </joint>

<!--............................................trnasmission...................................................... -->  

    <transmission name="rf_transmission">
        <type>transmission_interface/SimpleTransmission</type>
        <actuator name="rf_motor">
            <mechanicalReduction>1</mechanicalReduction>
        </actuator>
        <joint name="body_rf_wheel">
            <hardwareInterface>hardware_interface/PositionJointInterface</hardwareInterface>
        </joint>
    </transmission>

    <transmission name="rb_transmission">
        <type>transmission_interface/SimpleTransmission</type>
        <actuator name="rb_motor">
            <mechanicalReduction>1</mechanicalReduction>
        </actuator>
        <joint name="body_rb_wheel">
            <hardwareInterface>hardware_interface/PositionJointInterface</hardwareInterface>
        </joint>
    </transmission>

    <transmission name="lf_transmission">
        <type>transmission_interface/SimpleTransmission</type>
        <actuator name="lf_motor">
            <mechanicalReduction>1</mechanicalReduction>
        </actuator>
        <joint name="body_lf_wheel">
            <hardwareInterface>hardware_interface/PositionJointInterface</hardwareInterface>
        </joint>
    </transmission>

    <transmission name="lb_transmission">
        <type>transmission_interface/SimpleTransmission</type>
        <actuator name="lb_motor">
            <mechanicalReduction>1</mechanicalReduction>
        </actuator>
        <joint name="body_lb_wheel">
            <hardwareInterface>hardware_interface/PositionJointInterface</hardwareInterface>
        </joint>
    </transmission>


    <gazebo>
        <plugin name="skid_steer_drive_controller" filename="libgazebo_ros_skid_steer_drive.so">
   	        <updateRate>100.0</updateRate>
   	        <robotNamespace>/</robotNamespace>
   	        <leftFrontJoint>body_lf_wheel</leftFrontJoint>
   	        <rightFrontJoint>body_rf_wheel</rightFrontJoint>
   	        <leftRearJoint>body_lb_wheel</leftRearJoint>
   	        <rightRearJoint>body_rb_wheel</rightRearJoint>
  	        <wheelSeparation>0.2</wheelSeparation>
  	        <wheelDiameter>0.4</wheelDiameter>
	        <torque>100</torque>
  	        <robotBaseFrame>body</robotBaseFrame>
  	        <topicName>cmd_vel</topicName>
  	        <broadcastTF>false</broadcastTF>
  	    </plugin>
    </gazebo>

</robot>